Workbook

Sheet Dashboard
B1: PERSONAL FINANCE DASHBOARD · Dec 2025 – Mar 2026
B3: Tap the dropdowns below to filter — works in both Numbers and Excel
B4: MONTH | E4: CATEGORY | H4: PAYMENT METHOD
B5: All | E5: All | H5: All
B7: TOTAL SPEND | E7: MONTHLY AVG | H7: TRANSACTIONS | K7: TOP CATEGORY | N7: AVG PER TXN
B8: =SUMIFS(Transactions!$I$2:$I$122,Transactions!$E$2:$E$122,IF(Dashboard!$B$5="All","<>",Dashboard!$B$5),Transactions!$G$2:$G$122,IF(Dashboard!$E$5="All","<>",Dashboard!$E$5),Transactions!$J$2:$J$122,IF(Dashboard!$H$5="All","<>",Dashboard!$H$5)) -> 4506.53 | E8: =IFERROR(B8/COUNTIF(Summary_Tables!$F$2:$F$5,">0"),0) -> 1126.6325 | H8: =COUNTIFS(Transactions!$B$2:$B$122,"<>",Transactions!$E$2:$E$122,IF(Dashboard!$B$5="All","<>",Dashboard!$B$5),Transactions!$G$2:$G$122,IF(Dashboard!$E$5="All","<>",Dashboard!$E$5),Transactions!$J$2:$J$122,IF(Dashboard!$H$5="All","<>",Dashboard!$H$5)) -> 121 | K8: =INDEX(Summary_Tables!$A$2:$A$16,MATCH(MAX(Summary_Tables!$B$2:$B$16),Summary_Tables!$B$2:$B$16,0)) -> Shopping | N8: =IFERROR(B8/H8,0) -> 37.24405
B12: SPEND BY CATEGORY | H12: DAILY SPEND TREND
B25: MONTH-OVER-MONTH | H25: PAYMENT METHOD | L25: TOP MERCHANTS
B39: KEY INSIGHTS
B40: • Total outflow across 4 months: $4,506.53 — one-off charges account for $1,798 (40%), leaving $2,709 of recurring spend.
B41: • Recurring top category: Restaurants at $667 — this is the realistic lever for saving.
B42: • Restaurants + Coffee combined: $786 — a sizeable, fully-recurring discretionary slice.
B43: • BofA Credit carries 76% of your spend; Discover Card carries 24%.
B44: • Biggest single merchant is 'USCIS I-765 Fee' at $470.00.
B45: • Month-over-Month chart: orange bar = recurring only, navy = total incl. one-offs.

Sheet Transactions
A1: TransactionID | B1: Date | C1: Year | D1: Month | E1: YearMonth | F1: Description | G1: Category | H1: Category_Raw | I1: Amount | J1: Payment Method | K1: Weekday | L1: IsOneOff
A2: T0001 | B2: 46003 | C2: 2025 | D2: 12 | E2: 2025-12 | F2: Adidas US Online Store | G2: Shopping | H2: Merchandise | I2: 105 | J2: Discover Card | K2: Friday | L2: No
A3: T0002 | B3: 46015 | C3: 2025 | D3: 12 | E3: 2025-12 | F3: Desi Chowrastha Nashua NH | G3: Restaurants | H3: Restaurants | I3: 78.07 | J3: Discover Card | K3: Wednesday | L3: No
A4: T0003 | B4: 46019 | C4: 2025 | D4: 12 | E4: 2025-12 | F4: Nike.com | G4: Shopping | H4: Merchandise | I4: 165 | J4: Discover Card | K4: Sunday | L4: No
A5: T0004 | B5: 46021 | C5: 2025 | D5: 12 | E5: 2025-12 | F5: Milkshake Lovers Nashua NH | G5: Restaurants | H5: Restaurants | I5: 7.74 | J5: Discover Card | K5: Tuesday | L5: No
A6: T0005 | B6: 46021 | C6: 2025 | D6: 12 | E6: 2025-12 | F6: Desi Chowrastha Nashua NH | G6: Restaurants | H6: Restaurants | I6: 40.12 | J6: Discover Card | K6: Tuesday | L6: No
A7: T0006 | B7: 46021 | C7: 2025 | D7: 12 | E7: 2025-12 | F7: Desi Chowrastha Nashua NH | G7: Restaurants | H7: Restaurants | I7: 14.09 | J7: Discover Card | K7: Tuesday | L7: No
A8: T0007 | B8: 46021 | C8: 2025 | D8: 12 | E8: 2025-12 | F8: Whole Foods Nashua NH | G8: Groceries | H8: Supermarkets | I8: 13.77 | J8: Discover Card | K8: Tuesday | L8: No
A9: T0008 | B9: 46022 | C9: 2025 | D9: 12 | E9: 2025-12 | F9: Great Clips Nashua NH | G9: Personal Care | H9: Personal Care | I9: 23 | J9: BofA Credit | K9: Wednesday | L9: No
A10: T0009 | B10: 46022 | C10: 2025 | D10: 12 | E10: 2025-12 | F10: Trinity Realty II Cambridge MA | G10: Housing | H10: Housing | I10: 15 | J10: BofA Credit | K10: Wednesday | L10: No
A11: T0010 | B11: 46022 | C11: 2025 | D11: 12 | E11: 2025-12 | F11: 75 State St Garage Boston MA | G11: Transport | H11: Transport | I11: 18 | J11: BofA Credit | K11: Wednesday | L11: No
A12: T0011 | B12: 46022 | C12: 2025 | D12: 12 | E12: 2025-12 | F12: Maharaja Cambridge MA | G12: Restaurants | H12: Restaurants | I12: 213.9 | J12: Discover Card | K12: Wednesday | L12: No
A13: T0012 | B13: 46022 | C13: 2025 | D13: 12 | E13: 2025-12 | F13: OpenAI ChatGPT Subscription | G13: Subscriptions | H13: Subscriptions | I13: 20 | J13: BofA Credit | K13: Wednesday | L13: No
... A122: T0121 | B122: 46105 | C122: 2026 | D122: 3 | E122: 2026-03 | F122: Costco Online | G122: Shopping | H122: Shopping | I122: 30.99 | J122: BofA Credit | K122: Tuesday | L122: No

Sheet Summary_Tables
A1: Category | B1: Total | C1: Count | E1: YearMonth | F1: Total | G1: Recurring | I1: Payment Method | J1: Total | M1: Merchant | N1: Total | Q1: Date | R1: Spend
A2: Office Supplies | B2: =SUMIFS(Transactions!$I$2:$I$122,Transactions!$E$2:$E$122,IF(Dashboard!$B$5="All","<>",Dashboard!$B$5),Transactions!$G$2:$G$122,IF(Dashboard!$E$5="All","<>",Dashboard!$E$5),Transactions!$J$2:$J$122,IF(Dashboard!$H$5="All","<>",Dashboard!$H$5),Transactions!$G$2:$G$122,"Office Supplies") -> 12.69 | C2: =COUNTIFS(Transactions!$B$2:$B$122,"<>",Transactions!$E$2:$E$122,IF(Dashboard!$B$5="All","<>",Dashboard!$B$5),Transactions!$G$2:$G$122,IF(Dashboard!$E$5="All","<>",Dashboard!$E$5),Transactions!$J$2:$J$122,IF(Dashboard!$H$5="All","<>",Dashboard!$H$5),Transactions!$G$2:$G$122,"Office Supplies") -> 7 | E2: 2025-12 | F2: =SUMIFS(Transactions!$I$2:$I$122,Transactions!$E$2:$E$122,E2,Transactions!$G$2:$G$122,IF(Dashboard!$E$5="All","<>",Dashboard!$E$5),Transactions!$J$2:$J$122,IF(Dashboard!$H$5="All","<>",Dashboard!$H$5)) -> 713.69 | G2: =SUMIFS(Transactions!$I$2:$I$122,Transactions!$E$2:$E$122,E2,Transactions!$G$2:$G$122,IF(Dashboard!$E$5="All","<>",Dashboard!$E$5),Transactions!$J$2:$J$122,IF(Dashboard!$H$5="All","<>",Dashboard!$H$5),Transactions!$L$2:$L$122,"No") -> 713.69 | I2: BofA Credit | J2: =SUMIFS(Transactions!$I$2:$I$122,Transactions!$J$2:$J$122,I2,Transactions!$E$2:$E$122,IF(Dashboard!$B$5="All","<>",Dashboard!$B$5),Transactions!$G$2:$G$122,IF(Dashboard!$E$5="All","<>",Dashboard!$E$5)) -> 3426.92 | M2: Abercrombie & Fitch Burlington MA | N2: =SUMIFS(Transactions!$I$2:$I$122,Transactions!$E$2:$E$122,IF(Dashboard!$B$5="All","<>",Dashboard!$B$5),Transactions!$G$2:$G$122,IF(Dashboard!$E$5="All","<>",Dashboard!$E$5),Transactions!$J$2:$J$122,IF(Dashboard!$H$5="All","<>",Dashboard!$H$5),Transactions!$F$2:$F$122,"Abercrombie & Fitch Burlington MA") -> 165 | Q2: 01-10 | R2: =SUMIFS(Transactions!$I$2:$I$122,Transactions!$B$2:$B$122,"2026-01-10",Transactions!$G$2:$G$122,IF(Dashboard!$E$5="All","<>",Dashboard!$E$5),Transactions!$J$2:$J$122,IF(Dashboard!$H$5="All","<>",Dashboard!$H$5)) -> 251.51
A3: Housing | B3: =SUMIFS(Transactions!$I$2:$I$122,Transactions!$E$2:$E$122,IF(Dashboard!$B$5="All","<>",Dashboard!$B$5),Transactions!$G$2:$G$122,IF(Dashboard!$E$5="All","<>",Dashboard!$E$5),Transactions!$J$2:$J$122,IF(Dashboard!$H$5="All","<>",Dashboard!$H$5),Transactions!$G$2:$G$122,"Housing") -> 15 | C3: =COUNTIFS(Transactions!$B$2:$B$122,"<>",Transactions!$E$2:$E$122,IF(Dashboard!$B$5="All","<>",Dashboard!$B$5),Transactions!$G$2:$G$122,IF(Dashboard!$E$5="All","<>",Dashboard!$E$5),Transactions!$J$2:$J$122,IF(Dashboard!$H$5="All","<>",Dashboard!$H$5),Transactions!$G$2:$G$122,"Housing") -> 1 | E3: 2026-01 | F3: =SUMIFS(Transactions!$I$2:$I$122,Transactions!$E$2:$E$122,E3,Transactions!$G$2:$G$122,IF(Dashboard!$E$5="All","<>",Dashboard!$E$5),Transactions!$J$2:$J$122,IF(Dashboard!$H$5="All","<>",Dashboard!$H$5)) -> 2169.56 | G3: =SUMIFS(Transactions!$I$2:$I$122,Transactions!$E$2:$E$122,E3,Transactions!$G$2:$G$122,IF(Dashboard!$E$5="All","<>",Dashboard!$E$5),Transactions!$J$2:$J$122,IF(Dashboard!$H$5="All","<>",Dashboard!$H$5),Transactions!$L$2:$L$122,"No") -> 1044.7 | I3: Discover Card | J3: =SUMIFS(Transactions!$I$2:$I$122,Transactions!$J$2:$J$122,I3,Transactions!$E$2:$E$122,IF(Dashboard!$B$5="All","<>",Dashboard!$B$5),Transactions!$G$2:$G$122,IF(Dashboard!$E$5="All","<>",Dashboard!$E$5)) -> 1079.61 | M3: Schoharie Town Court NY | N3: =SUMIFS(Transactions!$I$2:$I$122,Transactions!$E$2:$E$122,IF(Dashboard!$B$5="All","<>",Dashboard!$B$5),Transactions!$G$2:$G$122,IF(Dashboard!$E$5="All","<>",Dashboard!$E$5),Transactions!$J$2:$J$122,IF(Dashboard!$H$5="All","<>",Dashboard!$H$5),Transactions!$F$2:$F$122,"Schoharie Town Court NY") -> 168 | Q3: 01-12 | R3: =SUMIFS(Transactions!$I$2:$I$122,Transactions!$B$2:$B$122,"2026-01-12",Transactions!$G$2:$G$122,IF(Dashboard!$E$5="All","<>",Dashboard!$E$5),Transactions!$J$2:$J$122,IF(Dashboard!$H$5="All","<>",Dashboard!$H$5)) -> 23.37
A4: Personal Care | B4: =SUMIFS(Transactions!$I$2:$I$122,Transactions!$E$2:$E$122,IF(Dashboard!$B$5="All","<>",Dashboard!$B$5),Transactions!$G$2:$G$122,IF(Dashboard!$E$5="All","<>",Dashboard!$E$5),Transactions!$J$2:$J$122,IF(Dashboard!$H$5="All","<>",Dashboard!$H$5),Transactions!$G$2:$G$122,"Personal Care") -> 47 | C4: =COUNTIFS(Transactions!$B$2:$B$122,"<>",Transactions!$E$2:$E$122,IF(Dashboard!$B$5="All","<>",Dashboard!$B$5),Transactions!$G$2:$G$122,IF(Dashboard!$E$5="All","<>",Dashboard!$E$5),Transactions!$J$2:$J$122,IF(Dashboard!$H$5="All","<>",Dashboard!$H$5),Transactions!$G$2:$G$122,"Personal Care") -> 2 | E4: 2026-02 | F4: =SUMIFS(Transactions!$I$2:$I$122,Transactions!$E$2:$E$122,E4,Transactions!$G$2:$G$122,IF(Dashboard!$E$5="All","<>",Dashboard!$E$5),Transactions!$J$2:$J$122,IF(Dashboard!$H$5="All","<>",Dashboard!$H$5)) -> 1348.56 | G4: =SUMIFS(Transactions!$I$2:$I$122,Transactions!$E$2:$E$122,E4,Transactions!$G$2:$G$122,IF(Dashboard!$E$5="All","<>",Dashboard!$E$5),Transactions!$J$2:$J$122,IF(Dashboard!$H$5="All","<>",Dashboard!$H$5),Transactions!$L$2:$L$122,"No") -> 675.81 | M4: Maharaja Cambridge MA | N4: =SUMIFS(Transactions!$I$2:$I$122,Transactions!$E$2:$E$122,IF(Dashboard!$B$5="All","<>",Dashboard!$B$5),Transactions!$G$2:$G$122,IF(Dashboard!$E$5="All","<>",Dashboard!$E$5),Transactions!$J$2:$J$122,IF(Dashboard!$H$5="All","<>",Dashboard!$H$5),Transactions!$F$2:$F$122,"Maharaja Cambridge MA") -> 213.9 | Q4: 01-13 | R4: =SUMIFS(Transactions!$I$2:$I$122,Transactions!$B$2:$B$122,"2026-01-13",Transactions!$G$2:$G$122,IF(Dashboard!$E$5="All","<>",Dashboard!$E$5),Transactions!$J$2:$J$122,IF(Dashboard!$H$5="All","<>",Dashboard!$H$5)) -> 99.84
A5: Services | B5: =SUMIFS(Transactions!$I$2:$I$122,Transactions!$E$2:$E$122,IF(Dashboard!$B$5="All","<>",Dashboard!$B$5),Transactions!$G$2:$G$122,IF(Dashboard!$E$5="All","<>",Dashboard!$E$5),Transactions!$J$2:$J$122,IF(Dashboard!$H$5="All","<>",Dashboard!$H$5),Transactions!$G$2:$G$122,"Services") -> 106.96 | C5: =COUNTIFS(Transactions!$B$2:$B$122,"<>",Transactions!$E$2:$E$122,IF(Dashboard!$B$5="All","<>",Dashboard!$B$5),Transactions!$G$2:$G$122,IF(Dashboard!$E$5="All","<>",Dashboard!$E$5),Transactions!$J$2:$J$122,IF(Dashboard!$H$5="All","<>",Dashboard!$H$5),Transactions!$G$2:$G$122,"Services") -> 2 | E5: 2026-03 | F5: =SUMIFS(Transactions!$I$2:$I$122,Transactions!$E$2:$E$122,E5,Transactions!$G$2:$G$122,IF(Dashboard!$E$5="All","<>",Dashboard!$E$5),Transactions!$J$2:$J$122,IF(Dashboard!$H$5="All","<>",Dashboard!$H$5)) -> 274.72 | G5: =SUMIFS(Transactions!$I$2:$I$122,Transactions!$E$2:$E$122,E5,Transactions!$G$2:$G$122,IF(Dashboard!$E$5="All","<>",Dashboard!$E$5),Transactions!$J$2:$J$122,IF(Dashboard!$H$5="All","<>",Dashboard!$H$5),Transactions!$L$2:$L$122,"No") -> 274.72 | M5: Costco Nashua NH | N5: =SUMIFS(Transactions!$I$2:$I$122,Transactions!$E$2:$E$122,IF(Dashboard!$B$5="All","<>",Dashboard!$B$5),Transactions!$G$2:$G$122,IF(Dashboard!$E$5="All","<>",Dashboard!$E$5),Transactions!$J$2:$J$122,IF(Dashboard!$H$5="All","<>",Dashboard!$H$5),Transactions!$F$2:$F$122,"Costco Nashua NH") -> 240.07 | Q5: 01-14 | R5: =SUMIFS(Transactions!$I$2:$I$122,Transactions!$B$2:$B$122,"2026-01-14",Transactions!$G$2:$G$122,IF(Dashboard!$E$5="All","<>",Dashboard!$E$5),Transactions!$J$2:$J$122,IF(Dashboard!$H$5="All","<>",Dashboard!$H$5)) -> 52.05
A6: Coffee | B6: =SUMIFS(Transactions!$I$2:$I$122,Transactions!$E$2:$E$122,IF(Dashboard!$B$5="All","<>",Dashboard!$B$5),Transactions!$G$2:$G$122,IF(Dashboard!$E$5="All","<>",Dashboard!$E$5),Transactions!$J$2:$J$122,IF(Dashboard!$H$5="All","<>",Dashboard!$H$5),Transactions!$G$2:$G$122,"Coffee") -> 119.65 | C6: =COUNTIFS(Transactions!$B$2:$B$122,"<>",Transactions!$E$2:$E$122,IF(Dashboard!$B$5="All","<>",Dashboard!$B$5),Transactions!$G$2:$G$122,IF(Dashboard!$E$5="All","<>",Dashboard!$E$5),Transactions!$J$2:$J$122,IF(Dashboard!$H$5="All","<>",Dashboard!$H$5),Transactions!$G$2:$G$122,"Coffee") -> 11 | M6: Patel Brothers Nashua NH | N6: =SUMIFS(Transactions!$I$2:$I$122,Transactions!$E$2:$E$122,IF(Dashboard!$B$5="All","<>",Dashboard!$B$5),Transactions!$G$2:$G$122,IF(Dashboard!$E$5="All","<>",Dashboard!$E$5),Transactions!$J$2:$J$122,IF(Dashboard!$H$5="All","<>",Dashboard!$H$5),Transactions!$F$2:$F$122,"Patel Brothers Nashua NH") -> 250.61 | Q6: 01-15 | R6: =SUMIFS(Transactions!$I$2:$I$122,Transactions!$B$2:$B$122,"2026-01-15",Transactions!$G$2:$G$122,IF(Dashboard!$E$5="All","<>",Dashboard!$E$5),Transactions!$J$2:$J$122,IF(Dashboard!$H$5="All","<>",Dashboard!$H$5)) -> 33.1
A7: Transport | B7: =SUMIFS(Transactions!$I$2:$I$122,Transactions!$E$2:$E$122,IF(Dashboard!$B$5="All","<>",Dashboard!$B$5),Transactions!$G$2:$G$122,IF(Dashboard!$E$5="All","<>",Dashboard!$E$5),Transactions!$J$2:$J$122,IF(Dashboard!$H$5="All","<>",Dashboard!$H$5),Transactions!$G$2:$G$122,"Transport") -> 142.92 | C7: =COUNTIFS(Transactions!$B$2:$B$122,"<>",Transactions!$E$2:$E$122,IF(Dashboard!$B$5="All","<>",Dashboard!$B$5),Transactions!$G$2:$G$122,IF(Dashboard!$E$5="All","<>",Dashboard!$E$5),Transactions!$J$2:$J$122,IF(Dashboard!$H$5="All","<>",Dashboard!$H$5),Transactions!$G$2:$G$122,"Transport") -> 11 | M7: Summit One Vanderbilt NY | N7: =SUMIFS(Transactions!$I$2:$I$122,Transactions!$E$2:$E$122,IF(Dashboard!$B$5="All","<>",Dashboard!$B$5),Transactions!$G$2:$G$122,IF(Dashboard!$E$5="All","<>",Dashboard!$E$5),Transactions!$J$2:$J$122,IF(Dashboard!$H$5="All","<>",Dashboard!$H$5),Transactions!$F$2:$F$122,"Summit One Vanderbilt NY") -> 262.4 | Q7: 01-16 | R7: =SUMIFS(Transactions!$I$2:$I$122,Transactions!$B$2:$B$122,"2026-01-16",Transactions!$G$2:$G$122,IF(Dashboard!$E$5="All","<>",Dashboard!$E$5),Transactions!$J$2:$J$122,IF(Dashboard!$H$5="All","<>",Dashboard!$H$5)) -> 15.57
A8: Fines/Legal | B8: =SUMIFS(Transactions!$I$2:$I$122,Transactions!$E$2:$E$122,IF(Dashboard!$B$5="All","<>",Dashboard!$B$5),Transactions!$G$2:$G$122,IF(Dashboard!$E$5="All","<>",Dashboard!$E$5),Transactions!$J$2:$J$122,IF(Dashboard!$H$5="All","<>",Dashboard!$H$5),Transactions!$G$2:$G$122,"Fines/Legal") -> 173.02 | C8: =COUNTIFS(Transactions!$B$2:$B$122,"<>",Transactions!$E$2:$E$122,IF(Dashboard!$B$5="All","<>",Dashboard!$B$5),Transactions!$G$2:$G$122,IF(Dashboard!$E$5="All","<>",Dashboard!$E$5),Transactions!$J$2:$J$122,IF(Dashboard!$H$5="All","<>",Dashboard!$H$5),Transactions!$G$2:$G$122,"Fines/Legal") -> 2 | M8: Mint Mobile Subscription | N8: =SUMIFS(Transactions!$I$2:$I$122,Transactions!$E$2:$E$122,IF(Dashboard!$B$5="All","<>",Dashboard!$B$5),Transactions!$G$2:$G$122,IF(Dashboard!$E$5="All","<>",Dashboard!$E$5),Transactions!$J$2:$J$122,IF(Dashboard!$H$5="All","<>",Dashboard!$H$5),Transactions!$F$2:$F$122,"Mint Mobile Subscription") -> 267.12 | Q8: 01-17 | R8: =SUMIFS(Transactions!$I$2:$I$122,Transactions!$B$2:$B$122,"2026-01-17",Transactions!$G$2:$G$122,IF(Dashboard!$E$5="All","<>",Dashboard!$E$5),Transactions!$J$2:$J$122,IF(Dashboard!$H$5="All","<>",Dashboard!$H$5)) -> 22.84
A9: Gasoline | B9: =SUMIFS(Transactions!$I$2:$I$122,Transactions!$E$2:$E$122,IF(Dashboard!$B$5="All","<>",Dashboard!$B$5),Transactions!$G$2:$G$122,IF(Dashboard!$E$5="All","<>",Dashboard!$E$5),Transactions!$J$2:$J$122,IF(Dashboard!$H$5="All","<>",Dashboard!$H$5),Transactions!$G$2:$G$122,"Gasoline") -> 259.7 | C9: =COUNTIFS(Transactions!$B$2:$B$122,"<>",Transactions!$E$2:$E$122,IF(Dashboard!$B$5="All","<>",Dashboard!$B$5),Transactions!$G$2:$G$122,IF(Dashboard!$E$5="All","<>",Dashboard!$E$5),Transactions!$J$2:$J$122,IF(Dashboard!$H$5="All","<>",Dashboard!$H$5),Transactions!$G$2:$G$122,"Gasoline") -> 14 | M9: Desi Chowrastha Nashua NH | N9: =SUMIFS(Transactions!$I$2:$I$122,Transactions!$E$2:$E$122,IF(Dashboard!$B$5="All","<>",Dashboard!$B$5),Transactions!$G$2:$G$122,IF(Dashboard!$E$5="All","<>",Dashboard!$E$5),Transactions!$J$2:$J$122,IF(Dashboard!$H$5="All","<>",Dashboard!$H$5),Transactions!$F$2:$F$122,"Desi Chowrastha Nashua NH") -> 287.33 | Q9: 01-19 | R9: =SUMIFS(Transactions!$I$2:$I$122,Transactions!$B$2:$B$122,"2026-01-19",Transactions!$G$2:$G$122,IF(Dashboard!$E$5="All","<>",Dashboard!$E$5),Transactions!$J$2:$J$122,IF(Dashboard!$H$5="All","<>",Dashboard!$H$5)) -> 68
A10: Entertainment | B10: =SUMIFS(Transactions!$I$2:$I$122,Transactions!$E$2:$E$122,IF(Dashboard!$B$5="All","<>",Dashboard!$B$5),Transactions!$G$2:$G$122,IF(Dashboard!$E$5="All","<>",Dashboard!$E$5),Transactions!$J$2:$J$122,IF(Dashboard!$H$5="All","<>",Dashboard!$H$5),Transactions!$G$2:$G$122,"Entertainment") -> 304.4 | C10: =COUNTIFS(Transactions!$B$2:$B$122,"<>",Transactions!$E$2:$E$122,IF(Dashboard!$B$5="All","<>",Dashboard!$B$5),Transactions!$G$2:$G$122,IF(Dashboard!$E$5="All","<>",Dashboard!$E$5),Transactions!$J$2:$J$122,IF(Dashboard!$H$5="All","<>",Dashboard!$H$5),Transactions!$G$2:$G$122,"Entertainment") -> 3 | M10: Eversource Utility Bill | N10: =SUMIFS(Transactions!$I$2:$I$122,Transactions!$E$2:$E$122,IF(Dashboard!$B$5="All","<>",Dashboard!$B$5),Transactions!$G$2:$G$122,IF(Dashboard!$E$5="All","<>",Dashboard!$E$5),Transactions!$J$2:$J$122,IF(Dashboard!$H$5="All","<>",Dashboard!$H$5),Transactions!$F$2:$F$122,"Eversource Utility Bill") -> 460.07 | Q10: 01-20 | R10: =SUMIFS(Transactions!$I$2:$I$122,Transactions!$B$2:$B$122,"2026-01-20",Transactions!$G$2:$G$122,IF(Dashboard!$E$5="All","<>",Dashboard!$E$5),Transactions!$J$2:$J$122,IF(Dashboard!$H$5="All","<>",Dashboard!$H$5)) -> 60.47
A11: Subscriptions | B11: =SUMIFS(Transactions!$I$2:$I$122,Transactions!$E$2:$E$122,IF(Dashboard!$B$5="All","<>",Dashboard!$B$5),Transactions!$G$2:$G$122,IF(Dashboard!$E$5="All","<>",Dashboard!$E$5),Transactions!$J$2:$J$122,IF(Dashboard!$H$5="All","<>",Dashboard!$H$5),Transactions!$G$2:$G$122,"Subscriptions") -> 384.56 | C11: =COUNTIFS(Transactions!$B$2:$B$122,"<>",Transactions!$E$2:$E$122,IF(Dashboard!$B$5="All","<>",Dashboard!$B$5),Transactions!$G$2:$G$122,IF(Dashboard!$E$5="All","<>",Dashboard!$E$5),Transactions!$J$2:$J$122,IF(Dashboard!$H$5="All","<>",Dashboard!$H$5),Transactions!$G$2:$G$122,"Subscriptions") -> 8 | M11: USCIS I-765 Fee | N11: =SUMIFS(Transactions!$I$2:$I$122,Transactions!$E$2:$E$122,IF(Dashboard!$B$5="All","<>",Dashboard!$B$5),Transactions!$G$2:$G$122,IF(Dashboard!$E$5="All","<>",Dashboard!$E$5),Transactions!$J$2:$J$122,IF(Dashboard!$H$5="All","<>",Dashboard!$H$5),Transactions!$F$2:$F$122,"USCIS I-765 Fee") -> 470 | Q11: 01-23 | R11: =SUMIFS(Transactions!$I$2:$I$122,Transactions!$B$2:$B$122,"2026-01-23",Transactions!$G$2:$G$122,IF(Dashboard!$E$5="All","<>",Dashboard!$E$5),Transactions!$J$2:$J$122,IF(Dashboard!$H$5="All","<>",Dashboard!$H$5)) -> 98.78
A12: Utilities | B12: =SUMIFS(Transactions!$I$2:$I$122,Transactions!$E$2:$E$122,IF(Dashboard!$B$5="All","<>",Dashboard!$B$5),Transactions!$G$2:$G$122,IF(Dashboard!$E$5="All","<>",Dashboard!$E$5),Transactions!$J$2:$J$122,IF(Dashboard!$H$5="All","<>",Dashboard!$H$5),Transactions!$G$2:$G$122,"Utilities") -> 460.07 | C12: =COUNTIFS(Transactions!$B$2:$B$122,"<>",Transactions!$E$2:$E$122,IF(Dashboard!$B$5="All","<>",Dashboard!$B$5),Transactions!$G$2:$G$122,IF(Dashboard!$E$5="All","<>",Dashboard!$E$5),Transactions!$J$2:$J$122,IF(Dashboard!$H$5="All","<>",Dashboard!$H$5),Transactions!$G$2:$G$122,"Utilities") -> 2 | Q12: 01-24 | R12: =SUMIFS(Transactions!$I$2:$I$122,Transactions!$B$2:$B$122,"2026-01-24",Transactions!$G$2:$G$122,IF(Dashboard!$E$5="All","<>",Dashboard!$E$5),Transactions!$J$2:$J$122,IF(Dashboard!$H$5="All","<>",Dashboard!$H$5)) -> 256.99
A13: Government | B13: =SUMIFS(Transactions!$I$2:$I$122,Transactions!$E$2:$E$122,IF(Dashboard!$B$5="All","<>",Dashboard!$B$5),Transactions!$G$2:$G$122,IF(Dashboard!$E$5="All","<>",Dashboard!$E$5),Transactions!$J$2:$J$122,IF(Dashboard!$H$5="All","<>",Dashboard!$H$5),Transactions!$G$2:$G$122,"Government") -> 470 | C13: =COUNTIFS(Transactions!$B$2:$B$122,"<>",Transactions!$E$2:$E$122,IF(Dashboard!$B$5="All","<>",Dashboard!$B$5),Transactions!$G$2:$G$122,IF(Dashboard!$E$5="All","<>",Dashboard!$E$5),Transactions!$J$2:$J$122,IF(Dashboard!$H$5="All","<>",Dashboard!$H$5),Transactions!$G$2:$G$122,"Government") -> 1 | Q13: 01-27 | R13: =SUMIFS(Transactions!$I$2:$I$122,Transactions!$B$2:$B$122,"2026-01-27",Transactions!$G$2:$G$122,IF(Dashboard!$E$5="All","<>",Dashboard!$E$5),Transactions!$J$2:$J$122,IF(Dashboard!$H$5="All","<>",Dashboard!$H$5)) -> 332.11
A14: Groceries | B14: =SUMIFS(Transactions!$I$2:$I$122,Transactions!$E$2:$E$122,IF(Dashboard!$B$5="All","<>",Dashboard!$B$5),Transactions!$G$2:$G$122,IF(Dashboard!$E$5="All","<>",Dashboard!$E$5),Transactions!$J$2:$J$122,IF(Dashboard!$H$5="All","<>",Dashboard!$H$5),Transactions!$G$2:$G$122,"Groceries") -> 620.41 | C14: =COUNTIFS(Transactions!$B$2:$B$122,"<>",Transactions!$E$2:$E$122,IF(Dashboard!$B$5="All","<>",Dashboard!$B$5),Transactions!$G$2:$G$122,IF(Dashboard!$E$5="All","<>",Dashboard!$E$5),Transactions!$J$2:$J$122,IF(Dashboard!$H$5="All","<>",Dashboard!$H$5),Transactions!$G$2:$G$122,"Groceries") -> 19 | Q14: 01-28 | R14: =SUMIFS(Transactions!$I$2:$I$122,Transactions!$B$2:$B$122,"2026-01-28",Transactions!$G$2:$G$122,IF(Dashboard!$E$5="All","<>",Dashboard!$E$5),Transactions!$J$2:$J$122,IF(Dashboard!$H$5="All","<>",Dashboard!$H$5)) -> 93.92
A15: Restaurants | B15: =SUMIFS(Transactions!$I$2:$I$122,Transactions!$E$2:$E$122,IF(Dashboard!$B$5="All","<>",Dashboard!$B$5),Transactions!$G$2:$G$122,IF(Dashboard!$E$5="All","<>",Dashboard!$E$5),Transactions!$J$2:$J$122,IF(Dashboard!$H$5="All","<>",Dashboard!$H$5),Transactions!$G$2:$G$122,"Restaurants") -> 666.68 | C15: =COUNTIFS(Transactions!$B$2:$B$122,"<>",Transactions!$E$2:$E$122,IF(Dashboard!$B$5="All","<>",Dashboard!$B$5),Transactions!$G$2:$G$122,IF(Dashboard!$E$5="All","<>",Dashboard!$E$5),Transactions!$J$2:$J$122,IF(Dashboard!$H$5="All","<>",Dashboard!$H$5),Transactions!$G$2:$G$122,"Restaurants") -> 26 | Q15: 01-30 | R15: =SUMIFS(Transactions!$I$2:$I$122,Transactions!$B$2:$B$122,"2026-01-30",Transactions!$G$2:$G$122,IF(Dashboard!$E$5="All","<>",Dashboard!$E$5),Transactions!$J$2:$J$122,IF(Dashboard!$H$5="All","<>",Dashboard!$H$5)) -> 88.26
A16: Shopping | B16: =SUMIFS(Transactions!$I$2:$I$122,Transactions!$E$2:$E$122,IF(Dashboard!$B$5="All","<>",Dashboard!$B$5),Transactions!$G$2:$G$122,IF(Dashboard!$E$5="All","<>",Dashboard!$E$5),Transactions!$J$2:$J$122,IF(Dashboard!$H$5="All","<>",Dashboard!$H$5),Transactions!$G$2:$G$122,"Shopping") -> 723.47 | C16: =COUNTIFS(Transactions!$B$2:$B$122,"<>",Transactions!$E$2:$E$122,IF(Dashboard!$B$5="All","<>",Dashboard!$B$5),Transactions!$G$2:$G$122,IF(Dashboard!$E$5="All","<>",Dashboard!$E$5),Transactions!$J$2:$J$122,IF(Dashboard!$H$5="All","<>",Dashboard!$H$5),Transactions!$G$2:$G$122,"Shopping") -> 12 | Q16: 01-31 | R16: =SUMIFS(Transactions!$I$2:$I$122,Transactions!$B$2:$B$122,"2026-01-31",Transactions!$G$2:$G$122,IF(Dashboard!$E$5="All","<>",Dashboard!$E$5),Transactions!$J$2:$J$122,IF(Dashboard!$H$5="All","<>",Dashboard!$H$5)) -> 29.73
Q17: 02-02 | R17: =SUMIFS(Transactions!$I$2:$I$122,Transactions!$B$2:$B$122,"2026-02-02",Transactions!$G$2:$G$122,IF(Dashboard!$E$5="All","<>",Dashboard!$E$5),Transactions!$J$2:$J$122,IF(Dashboard!$H$5="All","<>",Dashboard!$H$5)) -> 89.17
Q18: 02-03 | R18: =SUMIFS(Transactions!$I$2:$I$122,Transactions!$B$2:$B$122,"2026-02-03",Transactions!$G$2:$G$122,IF(Dashboard!$E$5="All","<>",Dashboard!$E$5),Transactions!$J$2:$J$122,IF(Dashboard!$H$5="All","<>",Dashboard!$H$5)) -> 20
Q19: 02-05 | R19: =SUMIFS(Transactions!$I$2:$I$122,Transactions!$B$2:$B$122,"2026-02-05",Transactions!$G$2:$G$122,IF(Dashboard!$E$5="All","<>",Dashboard!$E$5),Transactions!$J$2:$J$122,IF(Dashboard!$H$5="All","<>",Dashboard!$H$5)) -> 8.85
Q20: 02-07 | R20: =SUMIFS(Transactions!$I$2:$I$122,Transactions!$B$2:$B$122,"2026-02-07",Transactions!$G$2:$G$122,IF(Dashboard!$E$5="All","<>",Dashboard!$E$5),Transactions!$J$2:$J$122,IF(Dashboard!$H$5="All","<>",Dashboard!$H$5)) -> 4.18
Q21: 02-09 | R21: =SUMIFS(Transactions!$I$2:$I$122,Transactions!$B$2:$B$122,"2026-02-09",Transactions!$G$2:$G$122,IF(Dashboard!$E$5="All","<>",Dashboard!$E$5),Transactions!$J$2:$J$122,IF(Dashboard!$H$5="All","<>",Dashboard!$H$5)) -> 11.15
Q22: 02-10 | R22: =SUMIFS(Transactions!$I$2:$I$122,Transactions!$B$2:$B$122,"2026-02-10",Transactions!$G$2:$G$122,IF(Dashboard!$E$5="All","<>",Dashboard!$E$5),Transactions!$J$2:$J$122,IF(Dashboard!$H$5="All","<>",Dashboard!$H$5)) -> 55.95
Q23: 02-11 | R23: =SUMIFS(Transactions!$I$2:$I$122,Transactions!$B$2:$B$122,"2026-02-11",Transactions!$G$2:$G$122,IF(Dashboard!$E$5="All","<>",Dashboard!$E$5),Transactions!$J$2:$J$122,IF(Dashboard!$H$5="All","<>",Dashboard!$H$5)) -> 8.5
Q24: 02-13 | R24: =SUMIFS(Transactions!$I$2:$I$122,Transactions!$B$2:$B$122,"2026-02-13",Transactions!$G$2:$G$122,IF(Dashboard!$E$5="All","<>",Dashboard!$E$5),Transactions!$J$2:$J$122,IF(Dashboard!$H$5="All","<>",Dashboard!$H$5)) -> 70.06
Q25: 02-15 | R25: =SUMIFS(Transactions!$I$2:$I$122,Transactions!$B$2:$B$122,"2026-02-15",Transactions!$G$2:$G$122,IF(Dashboard!$E$5="All","<>",Dashboard!$E$5),Transactions!$J$2:$J$122,IF(Dashboard!$H$5="All","<>",Dashboard!$H$5)) -> 122.69
Q26: 02-16 | R26: =SUMIFS(Transactions!$I$2:$I$122,Transactions!$B$2:$B$122,"2026-02-16",Transactions!$G$2:$G$122,IF(Dashboard!$E$5="All","<>",Dashboard!$E$5),Transactions!$J$2:$J$122,IF(Dashboard!$H$5="All","<>",Dashboard!$H$5)) -> 24.93
Q27: 02-18 | R27: =SUMIFS(Transactions!$I$2:$I$122,Transactions!$B$2:$B$122,"2026-02-18",Transactions!$G$2:$G$122,IF(Dashboard!$E$5="All","<>",Dashboard!$E$5),Transactions!$J$2:$J$122,IF(Dashboard!$H$5="All","<>",Dashboard!$H$5)) -> 113.51
Q28: 02-19 | R28: =SUMIFS(Transactions!$I$2:$I$122,Transactions!$B$2:$B$122,"2026-02-19",Transactions!$G$2:$G$122,IF(Dashboard!$E$5="All","<>",Dashboard!$E$5),Transactions!$J$2:$J$122,IF(Dashboard!$H$5="All","<>",Dashboard!$H$5)) -> 8.34
Q29: 02-20 | R29: =SUMIFS(Transactions!$I$2:$I$122,Transactions!$B$2:$B$122,"2026-02-20",Transactions!$G$2:$G$122,IF(Dashboard!$E$5="All","<>",Dashboard!$E$5),Transactions!$J$2:$J$122,IF(Dashboard!$H$5="All","<>",Dashboard!$H$5)) -> 19.43
Q30: 02-21 | R30: =SUMIFS(Transactions!$I$2:$I$122,Transactions!$B$2:$B$122,"2026-02-21",Transactions!$G$2:$G$122,IF(Dashboard!$E$5="All","<>",Dashboard!$E$5),Transactions!$J$2:$J$122,IF(Dashboard!$H$5="All","<>",Dashboard!$H$5)) -> 59.16
Q31: 02-22 | R31: =SUMIFS(Transactions!$I$2:$I$122,Transactions!$B$2:$B$122,"2026-02-22",Transactions!$G$2:$G$122,IF(Dashboard!$E$5="All","<>",Dashboard!$E$5),Transactions!$J$2:$J$122,IF(Dashboard!$H$5="All","<>",Dashboard!$H$5)) -> 267.12
Q32: 02-23 | R32: =SUMIFS(Transactions!$I$2:$I$122,Transactions!$B$2:$B$122,"2026-02-23",Transactions!$G$2:$G$122,IF(Dashboard!$E$5="All","<>",Dashboard!$E$5),Transactions!$J$2:$J$122,IF(Dashboard!$H$5="All","<>",Dashboard!$H$5)) -> 173.02
Q33: 02-24 | R33: =SUMIFS(Transactions!$I$2:$I$122,Transactions!$B$2:$B$122,"2026-02-24",Transactions!$G$2:$G$122,IF(Dashboard!$E$5="All","<>",Dashboard!$E$5),Transactions!$J$2:$J$122,IF(Dashboard!$H$5="All","<>",Dashboard!$H$5)) -> 19.8
Q34: 02-25 | R34: =SUMIFS(Transactions!$I$2:$I$122,Transactions!$B$2:$B$122,"2026-02-25",Transactions!$G$2:$G$122,IF(Dashboard!$E$5="All","<>",Dashboard!$E$5),Transactions!$J$2:$J$122,IF(Dashboard!$H$5="All","<>",Dashboard!$H$5)) -> 232.61
Q35: 02-26 | R35: =SUMIFS(Transactions!$I$2:$I$122,Transactions!$B$2:$B$122,"2026-02-26",Transactions!$G$2:$G$122,IF(Dashboard!$E$5="All","<>",Dashboard!$E$5),Transactions!$J$2:$J$122,IF(Dashboard!$H$5="All","<>",Dashboard!$H$5)) -> 7.49
Q36: 02-28 | R36: =SUMIFS(Transactions!$I$2:$I$122,Transactions!$B$2:$B$122,"2026-02-28",Transactions!$G$2:$G$122,IF(Dashboard!$E$5="All","<>",Dashboard!$E$5),Transactions!$J$2:$J$122,IF(Dashboard!$H$5="All","<>",Dashboard!$H$5)) -> 32.6
Q37: 03-01 | R37: =SUMIFS(Transactions!$I$2:$I$122,Transactions!$B$2:$B$122,"2026-03-01",Transactions!$G$2:$G$122,IF(Dashboard!$E$5="All","<>",Dashboard!$E$5),Transactions!$J$2:$J$122,IF(Dashboard!$H$5="All","<>",Dashboard!$H$5)) -> 50.38
Q38: 03-02 | R38: =SUMIFS(Transactions!$I$2:$I$122,Transactions!$B$2:$B$122,"2026-03-02",Transactions!$G$2:$G$122,IF(Dashboard!$E$5="All","<>",Dashboard!$E$5),Transactions!$J$2:$J$122,IF(Dashboard!$H$5="All","<>",Dashboard!$H$5)) -> 30.9
Q39: 03-04 | R39: =SUMIFS(Transactions!$I$2:$I$122,Transactions!$B$2:$B$122,"2026-03-04",Transactions!$G$2:$G$122,IF(Dashboard!$E$5="All","<>",Dashboard!$E$5),Transactions!$J$2:$J$122,IF(Dashboard!$H$5="All","<>",Dashboard!$H$5)) -> 24
Q40: 03-11 | R40: =SUMIFS(Transactions!$I$2:$I$122,Transactions!$B$2:$B$122,"2026-03-11",Transactions!$G$2:$G$122,IF(Dashboard!$E$5="All","<>",Dashboard!$E$5),Transactions!$J$2:$J$122,IF(Dashboard!$H$5="All","<>",Dashboard!$H$5)) -> 138.45
...

Sheet Open in Numbers
A1: WHEN OPENING THIS IN APPLE NUMBERS
A3: 1. Double-click the .xlsx — Numbers will import it and may show a warning
A4: that some features were changed. Click 'Continue' — the dashboard is
A5: designed to survive the import.
A7: 2. The filter cells on the Dashboard (MONTH / CATEGORY / PAYMENT METHOD)
A8: become Numbers pop-up menus. Tap a cell, pick a value, and every KPI
A9: and chart recalculates automatically — same interactivity as Excel.
A11: 3. All formulas use plain cell ranges (e.g. Transactions!$H$2:$H$122),
A12: not Excel Table names — Numbers handles these natively.
A14: 4. Charts are standard bar / column / line / pie — Numbers re-renders
A15: them with its own style after import.
A17: 5. To save a native .numbers copy: File → Save As… → Numbers format.
... A24: has its own Print view; those settings are ignored.
